Traceback (most recent call last):
  File "/home/tuser/Desktop/ENGR498/ARULE4Python/DEMOS/DEMO1.py", line 86, in <module>
    subprocess.run(command, check=True)
  File "/usr/lib/python3.10/subprocess.py", line 526, in run
    raise CalledProcessError(retcode, process.args,
subprocess.CalledProcessError: Command '['/home/tuser/Desktop/ENGR498/ARULE4Python/arule_linux.out', 'DEMO1', '2', '0', '1', '/home/tuser/Desktop/ENGR498/ARULE4Python']' returned non-zero exit status 8.

1,23.3
2,23.6
3,23.7
4,23.8
5,23.6
6,23.9
7,23.7
8,23.4
9,23.75
10,23.8
11,23.2
12,23.6
13,23.7
14,23.3
15,23.8
16,23.4
17,23.2
18,23.6
19,23.9
20,23.7
21,23.8
22,23.4
23,23.6
24,23.2
25,23.6
26,23.913
27,23.821
28,23.427
29,23.626
30,23.386
31,23.45
32,23.209
33,23.265
34,23.62
35,23.4
36,23.3
37,23.7
38,23.6
39,23.5
